Workbook

Sheet CONFIG
A1: CONFIG - fill in the two yellow cells below, save, then run: python compare_migration.py <this workbook>
A3: CATIA migration report (.xlsx): | B3: MigrationReportOfHomegrown_Claude.xlsx
A4: SysML v2 source code (.txt/.sysml): | B4: Homegrown_generated_pilot.txt
A6: Legend: yellow cells are the only cells you need to edit (full file paths).
A7: Example: C:\models\MigrationReportOfmyproject.xlsx / C:\models\package MyModel.txt

Sheet ALL_ELEMENTS_1_7
A1: Element MetaType | B1: Element Name | C1: Qualified Name | D1: Element ID | E1: Kind | F1: Owner Qualified Name | G1: Applied Stereotypes
A2: Package | B2: Homegrown_ | C2: Homegrown_ | D2: _2024x_3_63f0215_1784284849468_779009_4000 | E2: Element | F2: Model
A3: Package | B3: Homegrown_Example1 | C3: Homegrown_::Homegrown_Example1 | D3: _2024x_3_63f0215_1784284216005_606458_3629 | E3: Element | F3: Homegrown_
A4: Block | B4: Homegrown_Block | C4: Homegrown_::Homegrown_Example1::Homegrown_Block | D4: _2024x_3_63f0215_1784284234665_578346_3633 | E4: Element | F4: Homegrown_::Homegrown_Example1 | G4: Block
A5: Proxy Port | B5: p1 | C5: Homegrown_::Homegrown_Example1::Homegrown_Block::p1 | D5: _2024x_3_63f0215_1784284265236_496882_3723 | E5: Element | F5: Homegrown_::Homegrown_Example1::Homegrown_Block | G5: ProxyPort
A6: Part Property | B6: homegrown_Block2 | C6: Homegrown_::Homegrown_Example1::Homegrown_Block::homegrown_Block2 | D6: _2024x_3_63f0215_1784284286730_412221_3762 | E6: Element | F6: Homegrown_::Homegrown_Example1::Homegrown_Block | G6: PartProperty
A7: Value Property | B7: value1 | C7: Homegrown_::Homegrown_Example1::Homegrown_Block::value1 | D7: _2024x_3_63f0215_1784284460212_253078_3995 | E7: Element | F7: Homegrown_::Homegrown_Example1::Homegrown_Block | G7: ValueProperty
A8: Block | B8: Homegrown_Block2 | C8: Homegrown_::Homegrown_Example1::Homegrown_Block2 | D8: _2024x_3_63f0215_1784284262194_675498_3692 | E8: Element | F8: Homegrown_::Homegrown_Example1 | G8: Block
A9: Proxy Port | B9: p1 | C9: Homegrown_::Homegrown_Example1::Homegrown_Block2::p1 | D9: _2024x_3_63f0215_1784284280900_263786_3741 | E9: Element | F9: Homegrown_::Homegrown_Example1::Homegrown_Block2 | G9: ProxyPort
A10: Association | C10: Homegrown_::Homegrown_Example1:: | D10: _2024x_3_63f0215_1784284286730_91874_3761 | E10: Element | F10: Homegrown_::Homegrown_Example1
A11: Property | C11: Homegrown_::Homegrown_Example1:::: | D11: _2024x_3_63f0215_1784284286730_857360_3763 | E11: Element | F11: Homegrown_::Homegrown_Example1::
A12: Signal | B12: Homegrown_signal | C12: Homegrown_::Homegrown_Example1::Homegrown_signal | D12: _2024x_3_63f0215_1784284314522_264673_3795 | E12: Element | F12: Homegrown_::Homegrown_Example1
A13: Package | B13: Homegrown_Example3 | C13: Homegrown_::Homegrown_Example3 | D13: _2024x_3_63f0215_1784284225793_363190_3631 | E13: Element | F13: Homegrown_
A14: Value Type | B14: Homegrown_valueType | C14: Homegrown_::Homegrown_Example3::Homegrown_valueType | D14: _2024x_3_63f0215_1784284309714_612206_3774 | E14: Element | F14: Homegrown_::Homegrown_Example3 | G14: ValueType
A15: Package | B15: Homegrown_Example2 | C15: Homegrown_::Homegrown_Example2 | D15: _2024x_3_63f0215_1784284225569_244227_3630 | E15: Element | F15: Homegrown_
A16: Activity | B16: Homegrown_Example2 | C16: Homegrown_::Homegrown_Example2::Homegrown_Example2 | D16: _2024x_3_63f0215_1784284340743_519051_3814 | E16: Element | F16: Homegrown_::Homegrown_Example2
A17: Allocated Activity Partition | C17: Homegrown_::Homegrown_Example2::Homegrown_Example2:: | D17: _2024x_3_63f0215_1784284361632_215137_3842 | E17: Element | F17: Homegrown_::Homegrown_Example2::Homegrown_Example2 | G17: AllocateActivityPartition
A18: Allocated Activity Partition | C18: Homegrown_::Homegrown_Example2::Homegrown_Example2:: | D18: _2024x_3_63f0215_1784284361642_752693_3845 | E18: Element | F18: Homegrown_::Homegrown_Example2::Homegrown_Example2 | G18: AllocateActivityPartition
A19: Object Flow | C19: Homegrown_::Homegrown_Example2::Homegrown_Example2:: | D19: _2024x_3_63f0215_1784284377842_630201_3932 | E19: Element | F19: Homegrown_::Homegrown_Example2::Homegrown_Example2
A20: Control Flow | C20: Homegrown_::Homegrown_Example2::Homegrown_Example2:: | D20: _2024x_3_63f0215_1784284386311_279312_3967 | E20: Element | F20: Homegrown_::Homegrown_Example2::Homegrown_Example2
A21: Control Flow | C21: Homegrown_::Homegrown_Example2::Homegrown_Example2:: | D21: _2024x_3_63f0215_1784284396172_578710_3977 | E21: Element | F21: Homegrown_::Homegrown_Example2::Homegrown_Example2
A22: Control Flow | C22: Homegrown_::Homegrown_Example2::Homegrown_Example2:: | D22: _2024x_3_63f0215_1784284400681_507237_3982 | E22: Element | F22: Homegrown_::Homegrown_Example2::Homegrown_Example2
A23: Control Flow | C23: Homegrown_::Homegrown_Example2::Homegrown_Example2:: | D23: _2024x_3_63f0215_1784284407410_958678_3993 | E23: Element | F23: Homegrown_::Homegrown_Example2::Homegrown_Example2
A24: Call Behavior Action | B24: Homegrown_cba1 | C24: Homegrown_::Homegrown_Example2::Homegrown_Example2::Homegrown_cba1 | D24: _2024x_3_63f0215_1784284367419_77834_3888 | E24: Element | F24: Homegrown_::Homegrown_Example2::Homegrown_Example2
A25: Output Pin | B25: output | C25: Homegrown_::Homegrown_Example2::Homegrown_Example2::Homegrown_cba1::output | D25: _2024x_3_63f0215_1784284374735_813595_3916 | E25: Element | F25: Homegrown_::Homegrown_Example2::Homegrown_Example2::Homegrown_cba1
A26: Call Behavior Action | B26: Homegrown_cba2 | C26: Homegrown_::Homegrown_Example2::Homegrown_Example2::Homegrown_cba2 | D26: _2024x_3_63f0215_1784284369195_804450_3902 | E26: Element | F26: Homegrown_::Homegrown_Example2::Homegrown_Example2
A27: Input Pin | B27: input | C27: Homegrown_::Homegrown_Example2::Homegrown_Example2::Homegrown_cba2::input | D27: _2024x_3_63f0215_1784284377845_226603_3934 | E27: Element | F27: Homegrown_::Homegrown_Example2::Homegrown_Example2::Homegrown_cba2
A28: Initial Node | C28: Homegrown_::Homegrown_Example2::Homegrown_Example2:: | D28: _2024x_3_63f0215_1784284384518_819029_3959 | E28: Element | F28: Homegrown_::Homegrown_Example2::Homegrown_Example2
A29: Merge Node | C29: Homegrown_::Homegrown_Example2::Homegrown_Example2:: | D29: _2024x_3_63f0215_1784284393000_34419_3970 | E29: Element | F29: Homegrown_::Homegrown_Example2::Homegrown_Example2
A30: Activity Final Node | C30: Homegrown_::Homegrown_Example2::Homegrown_Example2:: | D30: _2024x_3_63f0215_1784284404970_4482_3985 | E30: Element | F30: Homegrown_::Homegrown_Example2::Homegrown_Example2

Sheet MIGRATED_SUCCESS
A1: Element MetaType (v1.7) | B1: Element Name | C1: v1.7 Qualified Name | D1: Element ID | E1: Migrated To (v2 construct) | F1: v2 Qualified Name | G1: v2 Line(s) | H1: Match Type | I1: Notes
A2: Package | B2: Homegrown_ | C2: Homegrown_ | D2: _2024x_3_63f0215_1784284849468_779009_4000 | E2: package | F2: Homegrown_ | G2: 1 | H2: Qualified name
A3: Package | B3: Homegrown_Example1 | C3: Homegrown_::Homegrown_Example1 | D3: _2024x_3_63f0215_1784284216005_606458_3629 | E3: package | F3: Homegrown_::Homegrown_Example1 | G3: 4 | H3: Qualified name
A4: Block | B4: Homegrown_Block | C4: Homegrown_::Homegrown_Example1::Homegrown_Block | D4: _2024x_3_63f0215_1784284234665_578346_3633 | E4: part def | F4: Homegrown_::Homegrown_Example1::Homegrown_Block | G4: 5 | H4: Qualified name
A5: Block | B5: Homegrown_Block2 | C5: Homegrown_::Homegrown_Example1::Homegrown_Block2 | D5: _2024x_3_63f0215_1784284262194_675498_3692 | E5: part def | F5: Homegrown_::Homegrown_Example1::Homegrown_Block2 | G5: 10 | H5: Qualified name
A6: Proxy Port | B6: p1 | C6: Homegrown_::Homegrown_Example1::Homegrown_Block2::p1 | D6: _2024x_3_63f0215_1784284280900_263786_3741 | E6: port | F6: Homegrown_::Homegrown_Example1::Homegrown_Block2::p1 | G6: 11 | H6: Qualified name
A7: Part Property | B7: homegrown_Block2 | C7: Homegrown_::Homegrown_Example1::Homegrown_Block::homegrown_Block2 | D7: _2024x_3_63f0215_1784284286730_412221_3762 | E7: part | F7: Homegrown_::Homegrown_Example1::Homegrown_Block::homegrown_Block2 | G7: 7 | H7: Qualified name
A8: Proxy Port | B8: p1 | C8: Homegrown_::Homegrown_Example1::Homegrown_Block::p1 | D8: _2024x_3_63f0215_1784284265236_496882_3723 | E8: port | F8: Homegrown_::Homegrown_Example1::Homegrown_Block::p1 | G8: 6 | H8: Qualified name
A9: Value Property | B9: value1 | C9: Homegrown_::Homegrown_Example1::Homegrown_Block::value1 | D9: _2024x_3_63f0215_1784284460212_253078_3995 | E9: attribute | F9: Homegrown_::Homegrown_Example1::Homegrown_Block::value1 | G9: 8 | H9: Qualified name
A10: Signal | B10: Homegrown_signal | C10: Homegrown_::Homegrown_Example1::Homegrown_signal | D10: _2024x_3_63f0215_1784284314522_264673_3795 | E10: item def | F10: Homegrown_::Homegrown_Example1::Homegrown_signal | G10: 17 | H10: Qualified name
A11: Package | B11: Homegrown_Example2 | C11: Homegrown_::Homegrown_Example2 | D11: _2024x_3_63f0215_1784284225569_244227_3630 | E11: package | F11: Homegrown_::Homegrown_Example2 | G11: 23 | H11: Qualified name
A12: Activity | B12: Homegrown_Example2 | C12: Homegrown_::Homegrown_Example2::Homegrown_Example2 | D12: _2024x_3_63f0215_1784284340743_519051_3814 | E12: action def | F12: Homegrown_::Homegrown_Example2::Homegrown_Example2 | G12: 24 | H12: Qualified name
A13: Call Behavior Action | B13: Homegrown_cba1 | C13: Homegrown_::Homegrown_Example2::Homegrown_Example2::Homegrown_cba1 | D13: _2024x_3_63f0215_1784284367419_77834_3888 | E13: action | F13: Homegrown_::Homegrown_Example2::Homegrown_Example2::Homegrown_cba1 | G13: 25 | H13: Qualified name
... A16: Value Type | B16: Homegrown_valueType | C16: Homegrown_::Homegrown_Example3::Homegrown_valueType | D16: _2024x_3_63f0215_1784284309714_612206_3774 | E16: attribute def | F16: Homegrown_::Homegrown_Example3::Homegrown_valueType | G16: 21 | H16: Qualified name

Sheet MISSED_MIGRATIONS
A1: Category | B1: Element MetaType (v1.7) | C1: Element Name | D1: v1.7 Qualified Name | E1: Element ID | F1: Reason
A2: UNVERIFIABLE_UNNAMED | B2: Association | D2: Homegrown_::Homegrown_Example1:: | E2: _2024x_3_63f0215_1784284286730_91874_3761 | F2: Unnamed in v1.7 - cannot be verified by name matching; review manually
A3: UNVERIFIABLE_UNNAMED | B3: Property | D3: Homegrown_::Homegrown_Example1:::: | E3: _2024x_3_63f0215_1784284286730_857360_3763 | F3: Unnamed in v1.7 - cannot be verified by name matching; review manually

Sheet MIGRATION_SUMMARY
A1: Metric | B1: Count | C1: % of v1.7 elements
A2: v1.7 elements + diagrams exported (ALL_ELEMENTS_1_7) | B2: =COUNTA(ALL_ELEMENTS_1_7!A:A)-1 | C2: =IFERROR(B2/$B$2,"")
A3: of which diagrams | B3: =COUNTIF(ALL_ELEMENTS_1_7!E:E,"Diagram") | C3: =IFERROR(B3/$B$2,"")
A4: MIGRATED_SUCCESS - matched by qualified name | B4: =COUNTIF(MIGRATED_SUCCESS!H:H,"Qualified name") | C4: =IFERROR(B4/$B$2,"")
A5: MIGRATED_SUCCESS - matched by name only | B5: =COUNTIF(MIGRATED_SUCCESS!H:H,"Name*") | C5: =IFERROR(B5/$B$2,"")
A6: of which also flagged in CATIA report | B6: =COUNTIF(MIGRATED_SUCCESS!I:I,"*CATIA*") | C6: =IFERROR(B6/$B$2,"")
A7: Listed in CATIA not-migrated report (excluded) | B7: =B2-B4-B5-B8-B9-B10 | C7: =IFERROR(B7/$B$2,"")
A8: MISSED_MIGRATIONS - MISSING | B8: =COUNTIF(MISSED_MIGRATIONS!A:A,"MISSING") | C8: =IFERROR(B8/$B$2,"")
A9: MISSED_MIGRATIONS - REFERENCE_ONLY | B9: =COUNTIF(MISSED_MIGRATIONS!A:A,"REFERENCE_ONLY") | C9: =IFERROR(B9/$B$2,"")
A10: MISSED_MIGRATIONS - UNVERIFIABLE_UNNAMED | B10: =COUNTIF(MISSED_MIGRATIONS!A:A,"UNVERIFIABLE_UNNAMED") | C10: =IFERROR(B10/$B$2,"")
A11: Accounted for (migrated + CATIA-reported) | B11: =B4+B5+B7 | C11: =IFERROR(B11/$B$2,"")
A13: SysML v2 named declarations parsed | B13: 26
A14: SysML v2 unnamed declarations parsed | B14: 0
A15: CATIA report: not-migrated elements | B15: 14
A16: CATIA report: elements with lost properties | B16: 2
A18: CATIA report file | B18: MigrationReportOfHomegrown_Claude.xlsx
A19: SysML v2 source file | B19: Homegrown_generated_pilot.txt
A20: Generated | B20: 2026-10-22 03:11:11
A21: Excluded from ALL metrics above (see EXCLUDED_METATYPES sheet): Boolean Tagged Value, Diagram, Element Tagged Value, Integer Tagged Value, Literal Unlimited Natural, String Tagged Value | B21: =MAX(COUNTA(EXCLUDED_METATYPES!A:A)-1,0)
A23: Element Metatype | B23: Quantity | C23: % Migration Success
A24: Abstraction | B24: =COUNTIF(ALL_ELEMENTS_1_7!$A$2:$A$30,"Abstraction") | C24: =IFERROR(COUNTIF(MIGRATED_SUCCESS!$A$2:$A$16,"Abstraction")/B24,"")
A25: Accept Event Action | B25: =COUNTIF(ALL_ELEMENTS_1_7!$A$2:$A$30,"Accept Event Action") | C25: =IFERROR(COUNTIF(MIGRATED_SUCCESS!$A$2:$A$16,"Accept Event Action")/B25,"")
A26: Activity | B26: =COUNTIF(ALL_ELEMENTS_1_7!$A$2:$A$30,"Activity") | C26: =IFERROR(COUNTIF(MIGRATED_SUCCESS!$A$2:$A$16,"Activity")/B26,"")
A27: Activity Final Node | B27: =COUNTIF(ALL_ELEMENTS_1_7!$A$2:$A$30,"Activity Final Node") | C27: =IFERROR(COUNTIF(MIGRATED_SUCCESS!$A$2:$A$16,"Activity Final Node")/B27,"")
A28: Activity Parameter Node | B28: =COUNTIF(ALL_ELEMENTS_1_7!$A$2:$A$30,"Activity Parameter Node") | C28: =IFERROR(COUNTIF(MIGRATED_SUCCESS!$A$2:$A$16,"Activity Parameter Node")/B28,"")
A29: Activity Partition | B29: =COUNTIF(ALL_ELEMENTS_1_7!$A$2:$A$30,"Activity Partition") | C29: =IFERROR(COUNTIF(MIGRATED_SUCCESS!$A$2:$A$16,"Activity Partition")/B29,"")
A30: Allocate | B30: =COUNTIF(ALL_ELEMENTS_1_7!$A$2:$A$30,"Allocate") | C30: =IFERROR(COUNTIF(MIGRATED_SUCCESS!$A$2:$A$16,"Allocate")/B30,"")
A31: Allocated Activity Partition | B31: =COUNTIF(ALL_ELEMENTS_1_7!$A$2:$A$30,"Allocated Activity Partition") | C31: =IFERROR(COUNTIF(MIGRATED_SUCCESS!$A$2:$A$16,"Allocated Activity Partition")/B31,"")
A32: Association | B32: =COUNTIF(ALL_ELEMENTS_1_7!$A$2:$A$30,"Association") | C32: =IFERROR(COUNTIF(MIGRATED_SUCCESS!$A$2:$A$16,"Association")/B32,"")
A33: Binding Connector | B33: =COUNTIF(ALL_ELEMENTS_1_7!$A$2:$A$30,"Binding Connector") | C33: =IFERROR(COUNTIF(MIGRATED_SUCCESS!$A$2:$A$16,"Binding Connector")/B33,"")
A34: Block | B34: =COUNTIF(ALL_ELEMENTS_1_7!$A$2:$A$30,"Block") | C34: =IFERROR(COUNTIF(MIGRATED_SUCCESS!$A$2:$A$16,"Block")/B34,"")
A35: Call Behavior Action | B35: =COUNTIF(ALL_ELEMENTS_1_7!$A$2:$A$30,"Call Behavior Action") | C35: =IFERROR(COUNTIF(MIGRATED_SUCCESS!$A$2:$A$16,"Call Behavior Action")/B35,"")
A36: Comment | B36: =COUNTIF(ALL_ELEMENTS_1_7!$A$2:$A$30,"Comment") | C36: =IFERROR(COUNTIF(MIGRATED_SUCCESS!$A$2:$A$16,"Comment")/B36,"")
A37: Connector | B37: =COUNTIF(ALL_ELEMENTS_1_7!$A$2:$A$30,"Connector") | C37: =IFERROR(COUNTIF(MIGRATED_SUCCESS!$A$2:$A$16,"Connector")/B37,"")
A38: Connector End | B38: =COUNTIF(ALL_ELEMENTS_1_7!$A$2:$A$30,"Connector End") | C38: =IFERROR(COUNTIF(MIGRATED_SUCCESS!$A$2:$A$16,"Connector End")/B38,"")
A39: Constraint | B39: =COUNTIF(ALL_ELEMENTS_1_7!$A$2:$A$30,"Constraint") | C39: =IFERROR(COUNTIF(MIGRATED_SUCCESS!$A$2:$A$16,"Constraint")/B39,"")
A40: Constraint Block | B40: =COUNTIF(ALL_ELEMENTS_1_7!$A$2:$A$30,"Constraint Block") | C40: =IFERROR(COUNTIF(MIGRATED_SUCCESS!$A$2:$A$16,"Constraint Block")/B40,"")
A41: Constraint Parameter | B41: =COUNTIF(ALL_ELEMENTS_1_7!$A$2:$A$30,"Constraint Parameter") | C41: =IFERROR(COUNTIF(MIGRATED_SUCCESS!$A$2:$A$16,"Constraint Parameter")/B41,"")
A42: Constraint Property | B42: =COUNTIF(ALL_ELEMENTS_1_7!$A$2:$A$30,"Constraint Property") | C42: =IFERROR(COUNTIF(MIGRATED_SUCCESS!$A$2:$A$16,"Constraint Property")/B42,"")
A43: Control Flow | B43: =COUNTIF(ALL_ELEMENTS_1_7!$A$2:$A$30,"Control Flow") | C43: =IFERROR(COUNTIF(MIGRATED_SUCCESS!$A$2:$A$16,"Control Flow")/B43,"")
...

Sheet EXCLUDED_METATYPES
A1: Element MetaType | B1: Element Name | C1: Qualified Name | D1: Element ID | E1: Kind | F1: Owner Qualified Name | G1: Applied Stereotypes
A2: Diagram | B2: Homegrown_Example1 | C2: Homegrown_::Homegrown_Example1::Homegrown_Example1 | D2: _2024x_3_63f0215_1784284257147_394270_3634 | E2: Diagram | F2: Homegrown_::Homegrown_Example1 | G2: DiagramInfo
A3: String Tagged Value | D3: _2024x_3_63f0215_1784284257147_394270_3634_application_be00301_1073306188629_537791_2 | E3: Element | F3: Homegrown_::Homegrown_Example1::Homegrown_Example1
A4: String Tagged Value | D4: _2024x_3_63f0215_1784284257147_394270_3634_application_be00301_1073394345322_922552_1 | E4: Element | F4: Homegrown_::Homegrown_Example1::Homegrown_Example1
A5: String Tagged Value | D5: _2024x_3_63f0215_1784284257147_394270_3634_application_be00301_1077726770128_871366_1 | E5: Element | F5: Homegrown_::Homegrown_Example1::Homegrown_Example1
A6: String Tagged Value | D6: _2024x_3_63f0215_1784284257147_394270_3634_application_16_8beta_8ca0285_1257244649124_794756_344 | E6: Element | F6: Homegrown_::Homegrown_Example1::Homegrown_Example1
A7: Literal Unlimited Natural | C7: Homegrown_::Homegrown_Example2::Homegrown_Example2:::: | D7: _2024x_3_63f0215_1784284377843_714443_3933 | E7: Element | F7: Homegrown_::Homegrown_Example2::Homegrown_Example2::
A8: Literal Unlimited Natural | C8: Homegrown_::Homegrown_Example2::Homegrown_Example2:::: | D8: _2024x_3_63f0215_1784284386312_365900_3968 | E8: Element | F8: Homegrown_::Homegrown_Example2::Homegrown_Example2::
A9: Literal Unlimited Natural | C9: Homegrown_::Homegrown_Example2::Homegrown_Example2:::: | D9: _2024x_3_63f0215_1784284396173_189902_3978 | E9: Element | F9: Homegrown_::Homegrown_Example2::Homegrown_Example2::
A10: Literal Unlimited Natural | C10: Homegrown_::Homegrown_Example2::Homegrown_Example2:::: | D10: _2024x_3_63f0215_1784284400681_760349_3983 | E10: Element | F10: Homegrown_::Homegrown_Example2::Homegrown_Example2::
A11: Literal Unlimited Natural | C11: Homegrown_::Homegrown_Example2::Homegrown_Example2:::: | D11: _2024x_3_63f0215_1784284407410_9161_3994 | E11: Element | F11: Homegrown_::Homegrown_Example2::Homegrown_Example2::
A12: Diagram | B12: Homegrown_Example2 | C12: Homegrown_::Homegrown_Example2::Homegrown_Example2::Homegrown_Example2 | D12: _2024x_3_63f0215_1784284340743_195212_3813 | E12: Diagram | F12: Homegrown_::Homegrown_Example2::Homegrown_Example2 | G12: DiagramInfo
A13: String Tagged Value | D13: _2024x_3_63f0215_1784284340743_195212_3813_application_be00301_1073306188629_537791_2 | E13: Element | F13: Homegrown_::Homegrown_Example2::Homegrown_Example2::Homegrown_Example2
A14: String Tagged Value | D14: _2024x_3_63f0215_1784284340743_195212_3813_application_be00301_1073394345322_922552_1 | E14: Element | F14: Homegrown_::Homegrown_Example2::Homegrown_Example2::Homegrown_Example2
A15: String Tagged Value | D15: _2024x_3_63f0215_1784284340743_195212_3813_application_be00301_1077726770128_871366_1 | E15: Element | F15: Homegrown_::Homegrown_Example2::Homegrown_Example2::Homegrown_Example2
A16: String Tagged Value | D16: _2024x_3_63f0215_1784284340743_195212_3813_application_16_8beta_8ca0285_1257244649124_794756_344 | E16: Element | F16: Homegrown_::Homegrown_Example2::Homegrown_Example2::Homegrown_Example2
